[2024-12-04T20:09:13.715+0000] {local_task_job_runner.py:123} INFO - ::group::Pre task execution logs
[2024-12-04T20:09:13.813+0000] {taskinstance.py:2613} INFO - Dependencies all met for dep_context=non-requeueable deps ti=<TaskInstance: etl_client_activity_EFIMOVICH_EVGENII.transform_h manual__2024-12-04T20:08:50.962670+00:00 [queued]>
[2024-12-04T20:09:13.841+0000] {taskinstance.py:2613} INFO - Dependencies all met for dep_context=requeueable deps ti=<TaskInstance: etl_client_activity_EFIMOVICH_EVGENII.transform_h manual__2024-12-04T20:08:50.962670+00:00 [queued]>
[2024-12-04T20:09:13.843+0000] {taskinstance.py:2866} INFO - Starting attempt 1 of 1
[2024-12-04T20:09:26.652+0000] {taskinstance.py:2889} INFO - Executing <Task(PythonOperator): transform_h> on 2024-12-04 20:08:50.962670+00:00
[2024-12-04T20:09:26.718+0000] {warnings.py:112} WARNING - /home/***/.local/lib/python3.12/site-packages/***/task/task_runner/standard_task_runner.py:70: DeprecationWarning: This process (pid=82) is multi-threaded, use of fork() may lead to deadlocks in the child.
  pid = os.fork()

[2024-12-04T20:09:26.732+0000] {standard_task_runner.py:104} INFO - Running: ['***', 'tasks', 'run', 'etl_client_activity_EFIMOVICH_EVGENII', 'transform_h', 'manual__2024-12-04T20:08:50.962670+00:00', '--job-id', '74', '--raw', '--subdir', 'DAGS_FOLDER/etl_client_activity.py', '--cfg-path', '/tmp/tmpybmp6sul']
[2024-12-04T20:09:26.757+0000] {standard_task_runner.py:72} INFO - Started process 149 to run task
[2024-12-04T20:09:26.758+0000] {standard_task_runner.py:105} INFO - Job 74: Subtask transform_h
[2024-12-04T20:09:27.022+0000] {task_command.py:467} INFO - Running <TaskInstance: etl_client_activity_EFIMOVICH_EVGENII.transform_h manual__2024-12-04T20:08:50.962670+00:00 [running]> on host fbfc88a57984
[2024-12-04T20:09:31.967+0000] {job.py:229} INFO - Heartbeat recovered after 18.40 seconds
[2024-12-04T20:09:32.220+0000] {taskinstance.py:3132} INFO - Exporting env vars: AIRFLOW_CTX_DAG_OWNER='***' AIRFLOW_CTX_DAG_ID='etl_client_activity_EFIMOVICH_EVGENII' AIRFLOW_CTX_TASK_ID='transform_h' AIRFLOW_CTX_EXECUTION_DATE='2024-12-04T20:08:50.962670+00:00' AIRFLOW_CTX_TRY_NUMBER='1' AIRFLOW_CTX_DAG_RUN_ID='manual__2024-12-04T20:08:50.962670+00:00'
[2024-12-04T20:09:32.243+0000] {logging_mixin.py:190} INFO - Task instance is in running state
[2024-12-04T20:09:32.248+0000] {logging_mixin.py:190} INFO -  Previous state of the Task instance: queued
[2024-12-04T20:09:32.250+0000] {logging_mixin.py:190} INFO - Current task name:transform_h state:running start_date:2024-12-04 20:09:13.817633+00:00
[2024-12-04T20:09:32.253+0000] {logging_mixin.py:190} INFO - Dag name:etl_client_activity_EFIMOVICH_EVGENII and current dag run status:running
[2024-12-04T20:09:32.256+0000] {taskinstance.py:731} INFO - ::endgroup::
[2024-12-04T20:09:35.114+0000] {taskinstance.py:3311} ERROR - Task failed with exception
Traceback (most recent call last):
  File "/home/airflow/.local/lib/python3.12/site-packages/pandas/core/indexes/base.py", line 3791, in get_loc
    return self._engine.get_loc(casted_key)
           ^^^^^^^^^^^^^^^^^^^^^^^^^^^^^^^^
  File "index.pyx", line 152, in pandas._libs.index.IndexEngine.get_loc
  File "index.pyx", line 181, in pandas._libs.index.IndexEngine.get_loc
  File "pandas/_libs/hashtable_class_helper.pxi", line 7080, in pandas._libs.hashtable.PyObjectHashTable.get_item
  File "pandas/_libs/hashtable_class_helper.pxi", line 7088, in pandas._libs.hashtable.PyObjectHashTable.get_item
KeyError: 'date'

The above exception was the direct cause of the following exception:

Traceback (most recent call last):
  File "/home/airflow/.local/lib/python3.12/site-packages/airflow/models/taskinstance.py", line 767, in _execute_task
    result = _execute_callable(context=context, **execute_callable_kwargs)
             ^^^^^^^^^^^^^^^^^^^^^^^^^^^^^^^^^^^^^^^^^^^^^^^^^^^^^^^^^^^^^
  File "/home/airflow/.local/lib/python3.12/site-packages/airflow/models/taskinstance.py", line 733, in _execute_callable
    return ExecutionCallableRunner(
           ^^^^^^^^^^^^^^^^^^^^^^^^
  File "/home/airflow/.local/lib/python3.12/site-packages/airflow/utils/operator_helpers.py", line 252, in run
    return self.func(*args, **kwargs)
           ^^^^^^^^^^^^^^^^^^^^^^^^^^
  File "/home/airflow/.local/lib/python3.12/site-packages/airflow/models/baseoperator.py", line 417, in wrapper
    return func(self, *args, **kwargs)
           ^^^^^^^^^^^^^^^^^^^^^^^^^^^
  File "/home/airflow/.local/lib/python3.12/site-packages/airflow/operators/python.py", line 238, in execute
    return_value = self.execute_callable()
                   ^^^^^^^^^^^^^^^^^^^^^^^
  File "/home/airflow/.local/lib/python3.12/site-packages/airflow/operators/python.py", line 256, in execute_callable
    return runner.run(*self.op_args, **self.op_kwargs)
           ^^^^^^^^^^^^^^^^^^^^^^^^^^^^^^^^^^^^^^^^^^^
  File "/home/airflow/.local/lib/python3.12/site-packages/airflow/utils/operator_helpers.py", line 252, in run
    return self.func(*args, **kwargs)
           ^^^^^^^^^^^^^^^^^^^^^^^^^^
  File "/opt/airflow/dags/etl_client_activity.py", line 31, in transform_product_data
    transformed_data = transfrom(filtered_table, kwargs['ds'])  # Обрабатываем данные
                       ^^^^^^^^^^^^^^^^^^^^^^^^^^^^^^^^^^^^^^^
  File "/opt/airflow/dags/transform_script.py", line 21, in transfrom
    profit_table[profit_table['date'].isin(date_list)]
                 ~~~~~~~~~~~~^^^^^^^^
  File "/home/airflow/.local/lib/python3.12/site-packages/pandas/core/frame.py", line 3893, in __getitem__
    indexer = self.columns.get_loc(key)
              ^^^^^^^^^^^^^^^^^^^^^^^^^
  File "/home/airflow/.local/lib/python3.12/site-packages/pandas/core/indexes/base.py", line 3798, in get_loc
    raise KeyError(key) from err
KeyError: 'date'
[2024-12-04T20:09:35.223+0000] {logging_mixin.py:190} INFO - Task instance in failure state
[2024-12-04T20:09:35.224+0000] {logging_mixin.py:190} INFO - Task start:2024-12-04 20:09:13.817633+00:00 end:2024-12-04 20:09:35.215274+00:00 duration:21.397641
[2024-12-04T20:09:35.226+0000] {logging_mixin.py:190} INFO - Task:<Task(PythonOperator): transform_h> dag:<DAG: etl_client_activity_EFIMOVICH_EVGENII> dagrun:<DagRun etl_client_activity_EFIMOVICH_EVGENII @ 2024-12-04 20:08:50.962670+00:00: manual__2024-12-04T20:08:50.962670+00:00, state:running, queued_at: 2024-12-04 20:08:51.004957+00:00. externally triggered: True>
[2024-12-04T20:09:35.226+0000] {logging_mixin.py:190} INFO - Failure caused by 'date'
[2024-12-04T20:09:35.227+0000] {taskinstance.py:1225} INFO - Marking task as FAILED. dag_id=etl_client_activity_EFIMOVICH_EVGENII, task_id=transform_h, run_id=manual__2024-12-04T20:08:50.962670+00:00, execution_date=20241204T200850, start_date=20241204T200913, end_date=20241204T200935
[2024-12-04T20:09:35.278+0000] {taskinstance.py:340} INFO - ::group::Post task execution logs
[2024-12-04T20:09:35.281+0000] {standard_task_runner.py:124} ERROR - Failed to execute job 74 for task transform_h ('date'; 149)
Traceback (most recent call last):
  File "/home/airflow/.local/lib/python3.12/site-packages/pandas/core/indexes/base.py", line 3791, in get_loc
    return self._engine.get_loc(casted_key)
           ^^^^^^^^^^^^^^^^^^^^^^^^^^^^^^^^
  File "index.pyx", line 152, in pandas._libs.index.IndexEngine.get_loc
  File "index.pyx", line 181, in pandas._libs.index.IndexEngine.get_loc
  File "pandas/_libs/hashtable_class_helper.pxi", line 7080, in pandas._libs.hashtable.PyObjectHashTable.get_item
  File "pandas/_libs/hashtable_class_helper.pxi", line 7088, in pandas._libs.hashtable.PyObjectHashTable.get_item
KeyError: 'date'

The above exception was the direct cause of the following exception:

Traceback (most recent call last):
  File "/home/airflow/.local/lib/python3.12/site-packages/airflow/task/task_runner/standard_task_runner.py", line 117, in _start_by_fork
    ret = args.func(args, dag=self.dag)
          ^^^^^^^^^^^^^^^^^^^^^^^^^^^^^
  File "/home/airflow/.local/lib/python3.12/site-packages/airflow/cli/cli_config.py", line 49, in command
    return func(*args, **kwargs)
           ^^^^^^^^^^^^^^^^^^^^^
  File "/home/airflow/.local/lib/python3.12/site-packages/airflow/utils/cli.py", line 116, in wrapper
    return f(*args, **kwargs)
           ^^^^^^^^^^^^^^^^^^
  File "/home/airflow/.local/lib/python3.12/site-packages/airflow/cli/commands/task_command.py", line 483, in task_run
    task_return_code = _run_task_by_selected_method(args, _dag, ti)
                       ^^^^^^^^^^^^^^^^^^^^^^^^^^^^^^^^^^^^^^^^^^^^
  File "/home/airflow/.local/lib/python3.12/site-packages/airflow/cli/commands/task_command.py", line 256, in _run_task_by_selected_method
    return _run_raw_task(args, ti)
           ^^^^^^^^^^^^^^^^^^^^^^^
  File "/home/airflow/.local/lib/python3.12/site-packages/airflow/cli/commands/task_command.py", line 341, in _run_raw_task
    return ti._run_raw_task(
           ^^^^^^^^^^^^^^^^^
  File "/home/airflow/.local/lib/python3.12/site-packages/airflow/utils/session.py", line 97, in wrapper
    return func(*args, session=session, **kwargs)
           ^^^^^^^^^^^^^^^^^^^^^^^^^^^^^^^^^^^^^^
  File "/home/airflow/.local/lib/python3.12/site-packages/airflow/models/taskinstance.py", line 3005, in _run_raw_task
    return _run_raw_task(
           ^^^^^^^^^^^^^^
  File "/home/airflow/.local/lib/python3.12/site-packages/airflow/models/taskinstance.py", line 273, in _run_raw_task
    TaskInstance._execute_task_with_callbacks(
  File "/home/airflow/.local/lib/python3.12/site-packages/airflow/models/taskinstance.py", line 3159, in _execute_task_with_callbacks
    result = self._execute_task(context, task_orig)
             ^^^^^^^^^^^^^^^^^^^^^^^^^^^^^^^^^^^^^^
  File "/home/airflow/.local/lib/python3.12/site-packages/airflow/models/taskinstance.py", line 3183, in _execute_task
    return _execute_task(self, context, task_orig)
           ^^^^^^^^^^^^^^^^^^^^^^^^^^^^^^^^^^^^^^^
  File "/home/airflow/.local/lib/python3.12/site-packages/airflow/models/taskinstance.py", line 767, in _execute_task
    result = _execute_callable(context=context, **execute_callable_kwargs)
             ^^^^^^^^^^^^^^^^^^^^^^^^^^^^^^^^^^^^^^^^^^^^^^^^^^^^^^^^^^^^^
  File "/home/airflow/.local/lib/python3.12/site-packages/airflow/models/taskinstance.py", line 733, in _execute_callable
    return ExecutionCallableRunner(
           ^^^^^^^^^^^^^^^^^^^^^^^^
  File "/home/airflow/.local/lib/python3.12/site-packages/airflow/utils/operator_helpers.py", line 252, in run
    return self.func(*args, **kwargs)
           ^^^^^^^^^^^^^^^^^^^^^^^^^^
  File "/home/airflow/.local/lib/python3.12/site-packages/airflow/models/baseoperator.py", line 417, in wrapper
    return func(self, *args, **kwargs)
           ^^^^^^^^^^^^^^^^^^^^^^^^^^^
  File "/home/airflow/.local/lib/python3.12/site-packages/airflow/operators/python.py", line 238, in execute
    return_value = self.execute_callable()
                   ^^^^^^^^^^^^^^^^^^^^^^^
  File "/home/airflow/.local/lib/python3.12/site-packages/airflow/operators/python.py", line 256, in execute_callable
    return runner.run(*self.op_args, **self.op_kwargs)
           ^^^^^^^^^^^^^^^^^^^^^^^^^^^^^^^^^^^^^^^^^^^
  File "/home/airflow/.local/lib/python3.12/site-packages/airflow/utils/operator_helpers.py", line 252, in run
    return self.func(*args, **kwargs)
           ^^^^^^^^^^^^^^^^^^^^^^^^^^
  File "/opt/airflow/dags/etl_client_activity.py", line 31, in transform_product_data
    transformed_data = transfrom(filtered_table, kwargs['ds'])  # Обрабатываем данные
                       ^^^^^^^^^^^^^^^^^^^^^^^^^^^^^^^^^^^^^^^
  File "/opt/airflow/dags/transform_script.py", line 21, in transfrom
    profit_table[profit_table['date'].isin(date_list)]
                 ~~~~~~~~~~~~^^^^^^^^
  File "/home/airflow/.local/lib/python3.12/site-packages/pandas/core/frame.py", line 3893, in __getitem__
    indexer = self.columns.get_loc(key)
              ^^^^^^^^^^^^^^^^^^^^^^^^^
  File "/home/airflow/.local/lib/python3.12/site-packages/pandas/core/indexes/base.py", line 3798, in get_loc
    raise KeyError(key) from err
KeyError: 'date'
[2024-12-04T20:09:35.402+0000] {local_task_job_runner.py:266} INFO - Task exited with return code 1
[2024-12-04T20:09:35.500+0000] {taskinstance.py:3895} INFO - 0 downstream tasks scheduled from follow-on schedule check
[2024-12-04T20:09:35.503+0000] {local_task_job_runner.py:245} INFO - ::endgroup::
